Workbook

Sheet DAY TRADE
B2: DAY TRADE 0DTE | C2: 46126 | F2: 46126 | I2: 46127 | L2: 46129 | O2: 46129 | R2: 46136 | U2: 46137
C3: BEAR CALL SPREAD | F3: BULL CALL SPREAD | I3: IRON CONDOR | L3: BULL CALL SPREAD | O3: BULL CALL SPREAD | R3: BULL CALL SPREAD | U3: BEAR PUT SPREAD
D4: 0.47916667 | E4: 0.48472222 | G4: 0.57222222 | H4: 0.69375 | J4: 0.49375 | K4: 13:47/ 13:53 | M4: 0.43958333 | N4: 0.5625 | P4: 0.59861111 | Q4: 0.67986111 | S4: 0.45416667 | T4: 0.67013889 | V4: 0.58333333 | W4: 0.62291667
E5: =IF( E6 = "", "-", IFERROR( E6/D6-1, "-" ) ) -> -7.2109387e-06 | H5: =IF( H6 = "", "-", IFERROR( H6/G6-1, "-" ) ) -> 0.0011179398 | K5: =IF( K6 = "", "-", IFERROR( K6/J6-1, "-" ) ) -> -0.00078381115 | N5: =IF( N6 = "", "-", IFERROR( N6/M6-1, "-" ) ) -> 0.0075220321 | Q5: =IF( Q6 = "", "-", IFERROR( Q6/P6-1, "-" ) ) -> -0.0016662015 | T5: =IF( T6 = "", "-", IFERROR( T6/S6-1, "-" ) ) -> 0.0060596439 | W5: =IF( W6 = "", "-", IFERROR( W6/V6-1, "-" ) ) -> 0.00073110736
B6: SPX | D6: 6933.91 | E6: 6933.86 | G6: 6959.23 | H6: 6967.01 | J6: 6991.48 | K6: 6986 | M6: 7088.51 | N6: 7141.83 | P6: 7129.99 | Q6: 7118.11 | S6: 7117.58 | T6: 7160.71 | V6: 7167.21 | W6: 7172.45
B7: VIX | C7: - | D7: 18 | E7: 17.99 | F7: - | G7: 18.47 | H7: 18.4 | I7: - | J7: 17.88 | K7: 18.29 | L7: - | M7: 17.6 | N7: 17.4 | O7: - | P7: 17.41 | Q7: 17.75 | R7: - | S7: 19.24 | T7: 18.55 | U7: - | V7: 18.49 | W7: 18.52
E8: =IF( E7 = "", "-", IFERROR( E7/D7-1, "-" ) ) -> -0.00055555556 | H8: =IF( H7 = "", "-", IFERROR( H7/G7-1, "-" ) ) -> -0.0037899296 | K8: =IF( K7 = "", "-", IFERROR( K7/J7-1, "-" ) ) -> 0.022930649 | N8: =IF( N7 = "", "-", IFERROR( N7/M7-1, "-" ) ) -> -0.011363636 | Q8: =IF( Q7 = "", "-", IFERROR( Q7/P7-1, "-" ) ) -> 0.019529006 | T8: =IF( T7 = "", "-", IFERROR( T7/S7-1, "-" ) ) -> -0.035862786 | W8: =IF( W7 = "", "-", IFERROR( W7/V7-1, "-" ) ) -> 0.0016224986
B9: TRAVA DE ALTA | C9: =IFERROR( C10/D6 - 1, "-" ) -> 0.0044837617 | D9: Prêmio | E9: Prêmio | F9: =IFERROR( F10/G6 - 1, "-" ) -> 0.00082911472 | G9: Prêmio | H9: Prêmio | I9: =IFERROR( I10/J6 - 1, "-" ) -> 0.0040792507 | J9: Prêmio | K9: Prêmio | L9: =IFERROR( L10/M6 - 1, "-" ) -> 0.00091556618 | M9: Prêmio | N9: Prêmio | O9: =IFERROR( O10/P6 - 1, "-" ) -> 0.00070266578 | P9: Prêmio | Q9: Prêmio | R9: =IFERROR( R10/S6 - 1, "-" ) -> 0.0024474611 | S9: Prêmio | T9: Prêmio | U9: =IFERROR( U10/V6 - 1, "-" ) -> -1 | V9: Prêmio | W9: Prêmio
B10: Vender Call | C10: 6965 | D10: 3.95 | E10: =( 3.7 + 3.67 ) / 2 -> 3.685 | F10: 6965 | G10: -4.92 | H10: 4.6 | I10: 7020 | J10: 1.5 | K10: -0.67 | L10: 7095 | M10: -12.69 | N10: 47.8 | O10: 7135 | P10: -6.63 | Q10: 0.47 | R10: 7135 | S10: -8.26 | T10: 26.2
B11: Comprar Call | C11: 6980 | D11: 1.7 | E11: =( 1.6 + 1.57 ) / 2 -> 1.585 | F11: 6980 | G11: 1.62 | H11: -0.75 | I11: 7060 | J11: -0.28 | K11: 0.12 | L11: 7100 | M11: 10.34 | N11: -43 | O11: 7140 | P11: 4.63 | Q11: -0.27 | R11: 7140 | S11: 6.51 | T11: -21.35
B12: Delta | C12: =IF( OR( C10 = "", C11 = ""), "-", ABS(C11-C10) ) -> 15 | D12: =D10-D11 -> 2.25 | E12: =E10-E11 -> 2.1 | F12: =IF( OR( F10 = "", F11 = ""), "-", ABS(F11-F10) ) -> 15 | G12: =G10+G11 -> -3.3 | H12: =H10+H11 -> 3.85 | I12: =IF( OR( I10 = "", I11 = ""), "-", ABS(I11-I10) ) -> 40 | J12: =J10+J11 -> 1.22 | K12: =K10+K11 -> -0.55 | L12: =IF( OR( L10 = "", L11 = ""), "-", ABS(L11-L10) ) -> 5 | M12: =M10+M11 -> -2.35 | N12: =N10+N11 -> 4.8 | O12: =IF( OR( O10 = "", O11 = ""), "-", ABS(O11-O10) ) -> 5 | P12: =P10+P11 -> -2 | Q12: =Q10+Q11 -> 0.2 | R12: =IF( OR( R10 = "", R11 = ""), "-", ABS(R11-R10) ) -> 5 | S12: =S10+S11 -> -1.75 | T12: =T10+T11 -> 4.85 | U12: =IF( OR( U10 = "", U11 = ""), "-", ABS(U11-U10) ) -> - | V12: =V10+V11 -> 0 | W12: =W10+W11 -> 0
B14: TRAVA DE BAIXA | C14: =IFERROR( C15/D6 - 1, "-" ) -> -1 | D14: Prêmio | E14: Prêmio | F14: =IFERROR( F15/G6 - 1, "-" ) -> -1 | G14: Prêmio | H14: Prêmio | I14: =IFERROR( I15/J6 - 1, "-" ) -> -0.010223872 | J14: Prêmio | K14: Prêmio | L14: =IFERROR( L15/M6 - 1, "-" ) -> -1 | M14: Prêmio | N14: Prêmio | O14: =IFERROR( O15/P6 - 1, "-" ) -> -1 | P14: Prêmio | Q14: Prêmio | R14: =IFERROR( R15/S6 - 1, "-" ) -> -1 | S14: Prêmio | T14: Prêmio | U14: =IFERROR( U15/V6 - 1, "-" ) -> -0.0010059702 | V14: Prêmio | W14: Prêmio
B15: Vender Put | I15: 6920 | J15: 2.35 | K15: -3.75 | U15: 7160 | V15: -5.48 | W15: 2.28
B16: Comprar Put | I16: 6960 | J16: =-0.82 -> -0.82 | K16: 1.3 | U16: 7155 | V16: 4.13 | W16: -1.68
B17: Delta | C17: =IF( OR( C15 = "", C16 = ""), "-", ABS(C16-C15) ) -> - | D17: =D15-D16 -> 0 | E17: =E15-E16 -> 0 | F17: =IF( OR( F15 = "", F16 = ""), "-", ABS(F16-F15) ) -> - | G17: =G15-G16 -> 0 | H17: =H15-H16 -> 0 | I17: =IF( OR( I15 = "", I16 = ""), "-", ABS(I16-I15) ) -> 40 | J17: =J15+J16 -> 1.53 | K17: =K15+K16 -> -2.45 | L17: =IF( OR( L15 = "", L16 = ""), "-", ABS(L16-L15) ) -> - | M17: =M15+M16 -> 0 | N17: =N15-N16 -> 0 | O17: =IF( OR( O15 = "", O16 = ""), "-", ABS(O16-O15) ) -> - | P17: =P15+P16 -> 0 | Q17: =Q15-Q16 -> 0 | R17: =IF( OR( R15 = "", R16 = ""), "-", ABS(R16-R15) ) -> - | S17: =S15+S16 -> 0 | T17: =T15-T16 -> 0 | U17: =IF( OR( U15 = "", U16 = ""), "-", ABS(U16-U15) ) -> 5 | V17: =V15+V16 -> -1.35 | W17: =W15+W16 -> 0.6
C19: Risco | D19: Retorno | E19: Resultado | F19: Risco | G19: Retorno | H19: Resultado | I19: Risco | J19: Retorno | K19: Resultado | L19: Risco | M19: Retorno | N19: Resultado | O19: Risco | P19: Retorno | Q19: Resultado | R19: Risco | S19: Retorno | T19: Resultado | U19: Risco | V19: Retorno | W19: Resultado
B20: RESULTADO OPERAÇÃO | C20: =MAX( C12, C17 ) -> 15 | D20: =D12+D17 -> 2.25 | E20: =-(E12+E17) -> -2.1 | F20: =MAX( F12, F17 ) -> 15 | G20: =G12+G17 -> -3.3 | H20: =(H12+H17) -> 3.85 | I20: =MAX( I12, I17 ) -> 40 | J20: =J12+J17 -> 2.75 | K20: =(K12+K17) -> -3 | L20: =MAX( L12, L17 ) -> 5 | M20: =M12+M17 -> -2.35 | N20: =(N12+N17) -> 4.8 | O20: =MAX( O12, O17 ) -> 5 | P20: =P12+P17 -> -2 | Q20: =(Q12+Q17) -> 0.2 | R20: =MAX( R12, R17 ) -> 5 | S20: =S12+S17 -> -1.75 | T20: =(T12+T17) -> 4.85 | U20: =MAX( U12, U17 ) -> 5 | V20: =V12+V17 -> -1.35 | W20: =(W12+W17) -> 0.6
B22: Quantity | C22: - | D22: 2 | E22: =D22 -> 2 | F22: - | G22: 1 | H22: =G22 -> 1 | I22: - | J22: 2 | K22: =J22 -> 2 | L22: - | M22: 1 | N22: =M22 -> 1 | O22: - | P22: 2 | Q22: =P22 -> 2 | R22: - | S22: 2 | T22: =S22 -> 2 | U22: - | V22: 1 | W22: =V22 -> 1
B24: TOTAL | D24: =D22 * 100 * D20 -> 450 | E24: =E22 * 100 * E20 -> -420 | G24: =G22 * 100 * G20 -> -330 | H24: =H22 * 100 * H20 -> 385 | J24: =J22 * 100 * J20 -> 550 | K24: =K22 * 100 * K20 -> -600 | M24: =M22 * 100 * M20 -> -235 | N24: =N22 * 100 * N20 -> 480 | P24: =P22 * 100 * P20 -> -400 | Q24: =Q22 * 100 * Q20 -> 40 | S24: =S22 * 100 * S20 -> -350 | T24: =T22 * 100 * T20 -> 970 | V24: =V22 * 100 * V20 -> -135 | W24: =W22 * 100 * W20 -> 60
B27: Max Profit | C27: - | D27: =100 * D20 * D22 -> 450 | F27: - | G27: =(F20+G20) * 100 * G22 -> 1170 | I27: - | J27: =100 * J20 * J22 -> 550 | L27: - | M27: =100 * ( L20 + M20 ) * M22 -> 265 | O27: - | P27: =100 * ( O20 + P20 ) * P22 -> 600 | R27: - | S27: =100 * ( R20 + S20 ) * S22 -> 650 | U27: - | V27: =100 * ( U20 + V20 ) * V22 -> 365
B28: Stop Loss | D28: =D20 * 100 * D22 -> 450 | G28: =G20 * 100 * G22 -> -330 | J28: =J27 * -J22 -> -1100 | M28: =M20 * 100 * M22 -> -235 | P28: =P20 * 100 * P22 -> -400 | S28: =S20 * 100 * S22 -> -350 | V28: =V20 * 100 * V22 -> -135
B29: Max Loss | C29: - | D29: =IF( D27 = 0, 0, (-100 * C20 + D27) * D22 ) -> -2100 | F29: - | G29: =IF( G27 = 0, 0, (-100 * F20 + G27) * G22 ) -> -330 | I29: - | J29: =IF( J27 = 0, 0, (-100 * I20 + J27) * J22 ) -> -6900 | L29: - | M29: =M20 * 100 * M22 -> -235 | O29: - | P29: =P20 * 100 * P22 -> -400 | R29: - | S29: =S20 * 100 * S22 -> -350 | U29: - | V29: =V20 * 100 * V22 -> -135
B31: FECHAMENTO | C31: - | D31: =IFERROR( "1:" & TEXT( -D29/D27, "#" ), "-" ) -> 1:5 | E31: =ROUND( ( D20 + E20 ) * D22 * 100, 2 ) -> 30 | F31: - | G31: =IFERROR( "1:" & TEXT( -G27/G29, "#" ), "-" ) -> 1:4 | H31: =ROUND( ( G20 + H20 ) * G22 * 100, 2 ) -> 55 | I31: - | J31: =IFERROR( "1:" & TEXT( -J29/J27, "#" ), "-" ) -> 1:13 | K31: =ROUND( ( J20 + K20 ) * J22 * 100, 2 ) -> -50 | L31: - | M31: =IFERROR( "1:" & TEXT( -M27/M29, "#" ), "-" ) -> 1:1 | N31: =ROUND( ( M20 + N20 ) * M22 * 100, 2 ) -> 245 | O31: - | P31: =IFERROR( "1:" & TEXT( -P27/P29, "#" ), "-" ) -> 1:2 | Q31: =ROUND( ( P20 + Q20 ) * P22 * 100, 2 ) -> -360 | R31: - | S31: =IFERROR( "1:" & TEXT( -S27/S29, "#" ), "-" ) -> 1:2 | T31: =ROUND( ( S20 + T20 ) * S22 * 100, 2 ) -> 620 | U31: - | V31: =IFERROR( "1:" & TEXT( -V27/V29, "#" ), "-" ) -> 1:3 | W31: =ROUND( ( V20 + W20 ) * V22 * 100, 2 ) -> -75
E32: =IF( E31 = "", "-", IFERROR( E31/D27, "-" ) ) -> 0.066666667 | H32: =IF( H31 = "", "-", IFERROR( H31/G27, "-" ) ) -> 0.047008547 | K32: =IF( K31 = "", "-", IFERROR( K31/J27, "-" ) ) -> -0.090909091 | N32: =IF( N31 = "", "-", IFERROR( N31/M27, "-" ) ) -> 0.9245283 | Q32: =IF( Q31 = "", "-", IFERROR( Q31/P27, "-" ) ) -> -0.6 | T32: =IF( T31 = "", "-", IFERROR( T31/S27, "-" ) ) -> 0.95384615 | W32: =IF( W31 = "", "-", IFERROR( W31/V27, "-" ) ) -> -0.20547945
E33: =110 + E31 -> 140 | H33: =E33 + H31 -> 195 | K33: =H33 + K31 -> 145 | N33: =K33 + N31 -> 390 | Q33: =N33 + Q31 -> 30 | T33: =Q33 + T31 -> 650 | W33: =T33 + W31 -> 575
D34: Stop Trigger | G34: Stop Trigger | J34: Stop Trigger | K34: 2.4 | M34: Stop Trigger | N34: 4.8 | P34: Stop Trigger | S34: Stop Trigger | T34: 4.85 | V34: Stop Trigger
D35: Stop Limit | G35: Stop Limit | J35: Stop Limit | K35: 2.6 | M35: Stop Limit | N35: 4.8 | P35: Stop Limit | S35: Stop Limit | T35: 4.85 | V35: Stop Limit

Sheet OPERAÇÕES
B2: IRON CONDOR 0DTE | C2: 46101 | F2: 46104 | I2: 46105 | L2: 46106 | O2: =L2 + 1 -> 46107 | R2: =O2 + 1 -> 46108 | U2: 46113 | X2: 46119 | AA2: 46120 | AD2: 46121 | AG2: 46121 | AJ2: 46121 | AM2: 46126
D3: 0.44444444 | E3: 0.69513889 | G3: 0.45069444 | H3: 0.6875 | J3: 0.46527778 | K3: 0.66666667 | M3: 0.4375 | N3: 0.66666667 | P3: 0.4375 | Q3: 0.64583333 | S3: 0.44791667 | T3: 0.64583333 | V3: 0.45833333 | W3: 0.66666667 | Y3: 0.46180556 | Z3: 0.62152778 | AB3: 0.44444444 | AC3: 0.5625 | AE3: 0.47222222 | AF3: 0.475 | AH3: 0.51111111 | AI3: 0.51666667 | AK3: 0.52222222 | AN3: 0.47916667 | AO3: 0.48472222
E4: =E5/D5-1 -> 0.14695196 | H4: =H5/G5-1 -> 0.035553739 | K4: =IF( K5 = "", "-", IFERROR( K5/J5-1, "-" ) ) -> -0.018980275 | N4: =IF( N5 = "", "-", IFERROR( N5/M5-1, "-" ) ) -> 0.040290089 | Q4: =IF( Q5 = "", "-", IFERROR( Q5/P5-1, "-" ) ) -> 0.046614872 | T4: =IF( T5 = "", "-", IFERROR( T5/S5-1, "-" ) ) -> 0.049558724 | W4: =IF( W5 = "", "-", IFERROR( W5/V5-1, "-" ) ) -> -0.037757009 | Z4: =IF( Z5 = "", "-", IFERROR( Z5/Y5-1, "-" ) ) -> -0.017355982 | AC4: =IF( AC5 = "", "-", IFERROR( AC5/AB5-1, "-" ) ) -> - | AF4: =IF( AF5 = "", "-", IFERROR( AF5/AE5-1, "-" ) ) -> - | AL4: =IF( AL5 = "", "-", IFERROR( AL5/AK5-1, "-" ) ) -> - | AO4: =IF( AO5 = "", "-", IFERROR( AO5/AN5-1, "-" ) ) -> -0.00055555556 | AR4: =IF( AR5 = "", "-", IFERROR( AR5/AQ5-1, "-" ) ) -> -
B5: VIX | C5: - | D5: 24.77 | E5: 28.41 | F5: - | G5: 24.47 | H5: 25.34 | I5: - | J5: 26.87 | K5: 26.36 | L5: - | M5: 24.82 | N5: 25.82 | O5: - | P5: 27.03 | Q5: 28.29 | R5: - | S5: 29.46 | T5: 30.92 | U5: - | V5: 26.75 | W5: 25.74 | X5: - | Y5: 27.08 | Z5: 26.61 | AA5: - | AB5: 20.6 | AD5: - | AE5: 21 | AG5: - | AM5: - | AN5: 18 | AO5: 17.99 | AP5: -
B6: SPX | C6: 0.01 | D6: 6594.66 | E6: 6496 | F6: 0.015 | G6: 6600 | H6: 6616.45 | I6: 0.01 | J6: 6545 | K6: 6582 | L6: 0.01 | M6: 6633 | N6: 6585 | P6: 6591.9 | Q6: 6494 | S6: 6442 | T6: 6383 | U6: 0.01 | V6: 6500 | W6: 6553 | Y6: 6547 | Z6: 6590 | AB6: 6786 | AC6: 6774.41 | AE6: 6767 | AF6: 6769.45 | AN6: 6933.91 | AO6: 6933.86
E7: =E6/D6-1 -> -0.014960589 | H7: =H6/G6-1 -> 0.0024924242 | K7: =IF( K6 = "", "-", IFERROR( K6/J6-1, "-" ) ) -> 0.0056531704 | N7: =IF( N6 = "", "-", IFERROR( N6/M6-1, "-" ) ) -> -0.0072365445 | Q7: =IF( Q6 = "", "-", IFERROR( Q6/P6-1, "-" ) ) -> -0.01485156 | T7: =IF( T6 = "", "-", IFERROR( T6/S6-1, "-" ) ) -> -0.0091586464 | W7: =IF( W6 = "", "-", IFERROR( W6/V6-1, "-" ) ) -> 0.0081538462 | X7: =X9-Y6 -> 73 | Z7: =IF( Z6 = "", "-", IFERROR( Z6/Y6-1, "-" ) ) -> 0.0065678937 | AC7: =IF( AC6 = "", "-", IFERROR( AC6/AB6-1, "-" ) ) -> -0.0017079281 | AF7: =IF( AF6 = "", "-", IFERROR( AF6/AE6-1, "-" ) ) -> 0.00036205113 | AI7: =IF( AI6 = "", "-", IFERROR( AI6/AH6-1, "-" ) ) -> - | AL7: =IF( AL6 = "", "-", IFERROR( AL6/AK6-1, "-" ) ) -> - | AO7: =IF( AO6 = "", "-", IFERROR( AO6/AN6-1, "-" ) ) -> -7.2109387e-06 | AR7: =IF( AR6 = "", "-", IFERROR( AR6/AQ6-1, "-" ) ) -> -
B8: TRAVA DE ALTA | C8: Opção | D8: Prêmio | E8: Prêmio | F8: Opção | G8: Prêmio | H8: Prêmio | I8: Opção | J8: Prêmio | K8: Prêmio | L8: Opção | M8: Prêmio | N8: Prêmio | O8: =O9/P6 - 1 -> 0.0027457941 | P8: Prêmio | Q8: Prêmio | R8: =R9/S6 - 1 -> 0.011331885 | S8: Prêmio | T8: Prêmio | U8: Opção | V8: Prêmio | W8: Prêmio | X8: =X9/Y6 - 1 -> 0.011150145 | Y8: Prêmio | Z8: Prêmio | AA8: =IFERROR( AA9/AB6 - 1, "-" ) -> -1 | AB8: Prêmio | AC8: Prêmio | AD8: =IFERROR( AD9/AE6 - 1, "-" ) -> 0.0056154869 | AE8: Entrada | AF8: Saída | AG8: =IFERROR( AG9/AH6 - 1, "-" ) -> - | AH8: Entrada | AI8: Saída | AK8: Entrada | AL8: Saída | AM8: =IFERROR( AM9/AN6 - 1, "-" ) -> 0.0023204801 | AN8: Prêmio | AO8: Prêmio | AP8: =IFERROR( AP9/AQ6 - 1, "-" ) -> - | AQ8: Prêmio | AR8: Prêmio
B9: Vender Call | C9: =FLOOR( ROUND( D6 * ( 1 + C6 ), 0 ), 5 ) -> 6660 | D9: 2.6 | E9: 0 | F9: =FLOOR( ROUND( G6 * ( 1 + F6 ), 0 ), 5 ) -> 6695 | G9: 2.55 | H9: 0.1 | I9: =FLOOR( ROUND( J6 * ( 1 + I6 ), 0 ), 5 ) -> 6610 | J9: 1.7 | K9: 0.8 | L9: 6685 | M9: 1.83 | N9: 0.04 | O9: 6610 | P9: 2.6 | Q9: 0.01 | R9: 6515 | S9: 2.87 | T9: 0.38 | U9: 6590 | V9: 1.9 | W9: 1.3 | X9: 6620 | Y9: 3.93 | Z9: 2.25 | AD9: 6805 | AE9: 1.87 | AF9: 3.12 | AG9: 6825 | AH9: 1.57 | AI9: 3.67 | AJ9: 6840 | AK9: =( 2.55 + 2.27 ) / 2 -> 2.41 | AL9: 3.72 | AM9: 6950 | AN9: 3.95 | AO9: =( 3.7 + 3.67 ) / 2 -> 3.685 | AP9: 6965 | AQ9: -4.92 | AR9: 5
B10: Comprar Call | C10: =C9 + C19 -> 6700 | D10: 0.8 | E10: 0 | F10: =F9 + F19 -> 6735 | G10: 0.9 | H10: 0 | I10: =I9 + I19 -> 6650 | J10: 0.5 | K10: 0.25 | L10: 6725 | M10: 0.52 | N10: 0.03 | O10: =O9 + O11 -> 6650 | P10: 0.75 | Q10: 0.01 | R10: =R9 + R11 -> 6555 | S10: 1.32 | T10: 0.22 | U10: =U9 + U19 -> 6630 | V10: 0.65 | W10: 0.2 | X10: =X9 + X11 -> 6660 | Y10: 1.33 | Z10: 0.6 | AA10: =AA9 + AA11 -> 40 | AD10: 6860 | AE10: 0.42 | AF10: 0.47 | AG10: 6875 | AH10: 0.37 | AI10: 0.82 | AJ10: 6880 | AK10: =( 0.7 + 0.62 ) / 2 -> 0.66 | AL10: 1.07 | AM10: 6965 | AN10: 1.7 | AO10: =( 1.6 + 1.57 ) / 2 -> 1.585 | AP10: 6980 | AQ10: 1.62 | AR10: -1.1
B11: Delta | C11: - | D11: =D9-D10 -> 1.8 | E11: =E9-E10 -> 0 | F11: - | G11: =G9-G10 -> 1.65 | H11: =H9-H10 -> 0.1 | I11: =I10-I9 -> 40 | J11: =J9-J10 -> 1.2 | K11: =K9-K10 -> 0.55 | L11: =L10-L9 -> 40 | M11: =M9-M10 -> 1.31 | N11: =N9-N10 -> 0.01 | O11: 40 | P11: =P9-P10 -> 1.85 | Q11: =Q9-Q10 -> 0 | R11: 40 | S11: =S9-S10 -> 1.55 | T11: =T9-T10 -> 0.16 | U11: =U10-U9 -> 40 | V11: =V9-V10 -> 1.25 | W11: =W9-W10 -> 1.1 | X11: 40 | Y11: =Y9-Y10 -> 2.6 | Z11: =Z9-Z10 -> 1.65 | AA11: 40 | AB11: =AB9-AB10 -> 0 | AC11: =AC9-AC10 -> 0 | AD11: =AD10-AD9 -> 55 | AE11: =AE9-AE10 -> 1.45 | AF11: =AF9-AF10 -> 2.65 | AG11: =AG10-AG9 -> 50 | AH11: =AH9-AH10 -> 1.2 | AI11: =AI9-AI10 -> 2.85 | AJ11: =AJ10-AJ9 -> 40 | AK11: =AK9-AK10 -> 1.75 | AL11: =AL9-AL10 -> 2.65 | AM11: =IF( OR( AM9 = "", AM10 = ""), "-", ABS(AM10-AM9) ) -> 15 | AN11: =AN9-AN10 -> 2.25 | AO11: =AO9-AO10 -> 2.1 | AP11: =IF( OR( AP9 = "", AP10 = ""), "-", ABS(AP10-AP9) ) -> 15 | AQ11: =AQ9+AQ10 -> -3.3 | AR11: =AR9+AR10 -> 3.9
X12: =Y6-X14 -> 47
B13: TRAVA DE BAIXA | C13: Opção | D13: Prêmio | E13: Prêmio | F13: Opção | G13: Prêmio | H13: Prêmio | I13: Opção | J13: Prêmio | K13: Prêmio | L13: Opção | M13: Prêmio | N13: Prêmio | O13: =O14/P6 - 1 -> -0.013941352 | P13: Prêmio | Q13: Prêmio | R13: =R14/S6 - 1 -> -0.014281279 | S13: Prêmio | T13: Prêmio | U13: Opção | V13: Prêmio | W13: Prêmio | X13: =X14/Y6 - 1 -> -0.0071788605 | Y13: Prêmio | Z13: Prêmio | AA13: =IFERROR( AA14/AB6 - 1, "-" ) -> -0.0097259063 | AB13: Prêmio | AC13: Prêmio | AD13: =IFERROR( AD14/AE6 - 1, "-" ) -> -0.0069454707 | AE13: Prêmio | AF13: Prêmio | AG13: =IFERROR( AG14/AH6 - 1, "-" ) -> - | AH13: Prêmio | AI13: Prêmio | AK13: Entrada | AL13: Saída | AM13: =IFERROR( AM14/AN6 - 1, "-" ) -> -1 | AN13: Prêmio | AO13: Prêmio | AP13: =IFERROR( AP14/AQ6 - 1, "-" ) -> - | AQ13: Prêmio | AR13: Prêmio
B14: Vender Put | C14: =FLOOR( ROUND( D6 * ( 1 - C6 ), 0 ), 5 ) -> 6525 | D14: 2.95 | E14: 8.3 | F14: =FLOOR( ROUND( G6 * ( 1 - F6 ), 0 ), 5 ) -> 6500 | G14: 4.4 | H14: 0.1 | I14: =FLOOR( ROUND( J6 * ( 1 - I6 ), 0 ), 5 ) -> 6480 | J14: 5.9 | K14: 0.1 | L14: 6565 | M14: 7.1 | N14: 0.61 | O14: 6500 | P14: 3.25 | Q14: 13.97 | R14: 6350 | S14: 3.27 | T14: 4.06 | U14: 6380 | V14: 1.2 | W14: 0.15 | X14: 6500 | Y14: 4.07 | Z14: 0.22 | AA14: 6720 | AB14: 5.93 | AC14: 4.62 | AD14: 6720 | AE14: 2.27 | AF14: 0.47 | AJ14: 6790 | AK14: 3.12 | AL14: 1.07
B15: Comprar Put | C15: =C14-C19 -> 6485 | D15: 0.9 | E15: 0.55 | F15: =F14-F19 -> 6460 | G15: 2.05 | H15: 0 | I15: =I14-I19 -> 6440 | J15: 2.2 | K15: 0.1 | L15: 6525 | M15: 2.66 | N15: 0.07 | O15: =O14 - O16 -> 6455 | P15: 0.6 | Q15: 1.92 | R15: =R14 - R16 -> 6310 | S15: 1.22 | T15: 0.82 | U15: =U14-U19 -> 6340 | V15: 0.6 | W15: 0.05 | X15: =X14 - X16 -> 6460 | Y15: 1.37 | Z15: 0.12 | AA15: =AA14 - AA16 -> 6680 | AB15: 3.03 | AC15: 1.72 | AD15: 6680 | AE15: 0.87 | AF15: 0.27 | AJ15: 6750 | AK15: 0.82 | AL15: 0.47
B16: Delta | C16: - | D16: =D14-D15 -> 2.05 | E16: =E14-E15 -> 7.75 | F16: - | G16: =G14-G15 -> 2.35 | H16: =H14-H15 -> 0.1 | I16: =I14-I15 -> 40 | J16: =J14-J15 -> 3.7 | K16: =K14-K15 -> 0 | L16: =L14-L15 -> 40 | M16: =M14-M15 -> 4.44 | N16: =N14-N15 -> 0.54 | O16: 45 | P16: =P14-P15 -> 2.65 | Q16: =Q14-Q15 -> 12.05 | R16: 40 | S16: =S14-S15 -> 2.05 | T16: =T14-T15 -> 3.24 | U16: =U14-U15 -> 40 | V16: =V14-V15 -> 0.6 | W16: =W14-W15 -> 0.1 | X16: 40 | Y16: =Y14-Y15 -> 2.7 | Z16: =Z14-Z15 -> 0.1 | AA16: 40 | AB16: =AB14-AB15 -> 2.9 | AC16: =AC14-AC15 -> 2.9 | AD16: =AD15 - AD14 -> -40 | AE16: =AE14-AE15 -> 1.4 | AF16: =AF14-AF15 -> 0.2 | AG16: =AG15 - AG14 -> 0 | AH16: =AH14-AH15 -> 0 | AI16: =AI14-AI15 -> 0 | AJ16: =AJ15-AJ14 -> -40 | AK16: =AK14-AK15 -> 2.3 | AL16: =AL14-AL15 -> 0.6 | AM16: =IF( OR( AM14 = "", AM15 = ""), "-", ABS(AM15-AM14) ) -> - | AN16: =AN14-AN15 -> 0 | AO16: =AO14-AO15 -> 0 | AP16: =IF( OR( AP14 = "", AP15 = ""), "-", ABS(AP15-AP14) ) -> - | AQ16: =AQ14-AQ15 -> 0 | AR16: =AR14-AR15 -> 0
C18: Risco | D18: Retorno | E18: Resultado | F18: Risco | G18: Retorno | H18: Resultado | I18: Risco | J18: Retorno | K18: Resultado | L18: Risco | M18: Retorno | N18: Resultado | O18: Risco | P18: Retorno | Q18: Resultado | R18: Risco | S18: Retorno | T18: Resultado | U18: Risco | V18: Retorno | W18: Resultado | X18: Risco | Y18: Retorno | Z18: Resultado | AA18: Risco | AB18: Retorno | AC18: Resultado | AD18: Risco | AE18: Retorno | AF18: Resultado | AG18: Risco | AH18: Retorno | AI18: Resultado | AJ18: Risco | AK18: Retorno | AL18: Resultado | AM18: Risco | AN18: Retorno | AO18: Resultado | AP18: Risco | AQ18: Retorno | AR18: Resultado
B19: RESULTADO | C19: 40 | D19: =D11+D16 -> 3.85 | E19: =-(E11+E16) -> -7.75 | F19: 40 | G19: =G11+G16 -> 4 | H19: =-(H11+H16) -> -0.2 | I19: 40 | J19: =J11+J16 -> 4.9 | K19: =-(K11+K16) -> -0.55 | L19: 40 | M19: =M11+M16 -> 5.75 | N19: =-(N11+N16) -> -0.55 | O19: =MAX( O11, O16 ) -> 45 | P19: =P11+P16 -> 4.5 | Q19: =-(Q11+Q16) -> -12.05 | R19: =MAX( R11, R16 ) -> 40 | S19: =S11+S16 -> 3.6 | T19: =-(T11+T16) -> -3.4 | U19: 40 | V19: =V11+V16 -> 1.85 | W19: =-(W11+W16) -> -1.2 | X19: =MAX( X11, X16 ) -> 40 | Y19: =Y11+Y16 -> 5.3 | Z19: =-(Z11+Z16) -> -1.75 | AA19: =MAX( AA11, AA16 ) -> 40 | AB19: =AB11+AB16 -> 2.9 | AC19: =-(AC11+AC16) -> -2.9 | AD19: =MAX( AD11, AD16 ) -> 55 | AE19: =AE11+AE16 -> 2.85 | AF19: =-(AF11+AF16) -> -2.85 | AG19: =MAX( AG11, AG16 ) -> 50 | AH19: =AH11+AH16 -> 1.2 | AI19: =-(AI11+AI16) -> -2.85 | AJ19: =MAX( AJ11, AJ16 ) -> 40 | AK19: =AK11+AK16 -> 4.05 | AL19: =-(AL11+AL16) -> -3.25 | AM19: =MAX( AM11, AM16 ) -> 15 | AN19: =AN11+AN16 -> 2.25 | AO19: =-(AO11+AO16) -> -2.1 | AP19: =MAX( AP11, AP16 ) -> 15 | AQ19: =AQ11+AQ16 -> -3.3 | AR19: =(AR11+AR16) -> 3.9
B21: Quantity | C21: - | D21: 1 | E21: - | F21: - | G21: 1 | H21: - | I21: - | J21: 1 | K21: - | L21: - | M21: 2 | N21: - | O21: - | P21: 2 | Q21: - | R21: - | S21: 2 | T21: - | U21: - | V21: 2 | W21: - | X21: - | Y21: 2 | Z21: - | AA21: - | AB21: 2 | AC21: - | AD21: - | AE21: 2 | AF21: - | AG21: - | AH21: 2 | AI21: - | AJ21: - | AK21: 2 | AL21: - | AM21: - | AN21: 2 | AO21: - | AP21: - | AQ21: 1 | AR21: -
B22: Max Profit | C22: - | D22: =100 * D19 * D21 -> 385 | F22: - | G22: =100 * G19 * G21 -> 400 | I22: - | J22: =100 * J19 * J21 -> 490 | L22: - | M22: =100 * M19 * M21 -> 1150 | O22: - | P22: =100 * P19 * P21 -> 900 | R22: - | S22: =100 * S19 * S21 -> 720 | U22: - | V22: =100 * V19 * V21 -> 370 | X22: - | Y22: =100 * Y19 * Y21 -> 1060 | AA22: - | AB22: =100 * AB19 * AB21 -> 580 | AD22: - | AE22: =100 * AE19 * AE21 -> 570 | AG22: - | AH22: =100 * AH19 * AH21 -> 240 | AJ22: - | AK22: =100 * AK19 * AK21 -> 810 | AM22: - | AN22: =100 * AN19 * AN21 -> 450 | AP22: - | AQ22: =100 * AQ19 * AQ21 -> -330
B23: Stop Loss | D23: =D22 * -2 -> -770 | G23: =G22 * -2 -> -800 | J23: =J22 * -2 -> -980 | M23: =M22 * -2 -> -2300 | P23: =P22 * -2 -> -1800 | S23: =S22 * -2 -> -1440 | V23: =V22 * -2 -> -740 | Y23: =Y22 * -2 -> -2120 | AB23: =AB22 * -2 -> -1160 | AE23: =AE22 * -2 -> -1140 | AH23: =AH22 * -2 -> -480 | AK23: =AK22 * -2 -> -1620 | AN23: =AN22 * -2 -> -900 | AQ23: =AQ22 * -2 -> 660
B24: Max Loss | C24: - | D24: =IF( D22 = 0, 0, (-100 * C19 + D22) * D21 ) -> -3615 | F24: - | G24: =IF( G22 = 0, 0, (-100 * F19 + G22) * G21 ) -> -3600 | I24: - | J24: =IF( J22 = 0, 0, (-100 * I19 + J22) * J21 ) -> -3510 | L24: - | M24: =IF( M22 = 0, 0, (-100 * L19 + M22) * M21 ) -> -5700 | O24: - | P24: =IF( P22 = 0, 0, (-100 * O19 + P22) * P21 ) -> -7200 | R24: - | S24: =IF( S22 = 0, 0, (-100 * R19 + S22) * S21 ) -> -6560 | U24: - | V24: =IF( V22 = 0, 0, (-100 * U19 + V22) * V21 ) -> -7260 | X24: - | Y24: =IF( Y22 = 0, 0, (-100 * X19 + Y22) * Y21 ) -> -5880 | AA24: - | AB24: =IF( AB22 = 0, 0, (-100 * AA19 + AB22) * AB21 ) -> -6840 | AD24: - | AE24: =IF( AE22 = 0, 0, (-100 * AD19 + AE22) * AE21 ) -> -9860 | AG24: - | AH24: =IF( AH22 = 0, 0, (-100 * AG19 + AH22) * AH21 ) -> -9520 | AJ24: - | AK24: =IF( AK22 = 0, 0, (-100 * AJ19 + AK22) * AK21 ) -> -6380 | AM24: - | AN24: =IF( AN22 = 0, 0, (-100 * AM19 + AN22) * AN21 ) -> -2100 | AP24: - | AQ24: =IF( AQ22 = 0, 0, (-100 * AP19 + AQ22) * AQ21 ) -> -1830
B26: FECHAMENTO | C26: - | D26: =IFERROR( "1:" & TEXT( -D24/D22, "#" ), "-" ) -> 1:9 | E26: =ROUND( ( D19 + E19 ) * D21 * 100, 2 ) -> -390 | F26: - | G26: =IFERROR( "1:" & TEXT( -G24/G22, "#" ), "-" ) -> 1:9 | H26: =ROUND( ( G19 + H19 ) * G21 * 100, 2 ) -> 380 | I26: - | J26: =IFERROR( "1:" & TEXT( -J24/J22, "#" ), "-" ) -> 1:7 | K26: =ROUND( ( J19 + K19 ) * J21 * 100, 2 ) -> 435 | L26: - | M26: =IFERROR( "1:" & TEXT( -M24/M22, "#" ), "-" ) -> 1:5 | N26: =ROUND( ( M19 + N19 ) * M21 * 100, 2 ) -> 1040 | O26: - | P26: =IFERROR( "1:" & TEXT( -P24/P22, "#" ), "-" ) -> 1:8 | Q26: =ROUND( ( P19 + Q19 ) * P21 * 100, 2 ) -> -1510 | R26: - | S26: =IFERROR( "1:" & TEXT( -S24/S22, "#" ), "-" ) -> 1:9 | T26: =ROUND( ( S19 + T19 ) * S21 * 100, 2 ) -> 40 | U26: - | V26: =IFERROR( "1:" & TEXT( -V24/V22, "#" ), "-" ) -> 1:20 | W26: =ROUND( ( V19 + W19 ) * V21 * 100, 2 ) -> 130 | X26: - | Y26: =IFERROR( "1:" & TEXT( -Y24/Y22, "#" ), "-" ) -> 1:6 | Z26: =ROUND( ( Y19 + Z19 ) * Y21 * 100, 2 ) -> 710 | AA26: - | AB26: =IFERROR( "1:" & TEXT( -AB24/AB22, "#" ), "-" ) -> 1:12 | AC26: =ROUND( ( AB19 + AC19 ) * AB21 * 100, 2 ) -> 0 | AD26: - | AE26: =IFERROR( "1:" & TEXT( -AE24/AE22, "#" ), "-" ) -> 1:17 | AF26: =ROUND( ( AE19 + AF19 ) * AE21 * 100, 2 ) -> 0 | AG26: - | AH26: =IFERROR( "1:" & TEXT( -AH24/AH22, "#" ), "-" ) -> 1:40 | AI26: =ROUND( ( AH19 + AI19 ) * AH21 * 100, 2 ) -> -330 | AJ26: - | AK26: =IFERROR( "1:" & TEXT( -AK24/AK22, "#" ), "-" ) -> 1:8 | AL26: =ROUND( ( AK19 + AL19 ) * AK21 * 100, 2 ) -> 160 | AM26: - | AN26: =IFERROR( "1:" & TEXT( -AN24/AN22, "#" ), "-" ) -> 1:5 | AO26: =ROUND( ( AN19 + AO19 ) * AN21 * 100, 2 ) -> 30 | AP26: - | AQ26: =IFERROR( "1:" & TEXT( -AQ24/AQ22, "#" ), "-" ) -> 1:-6 | AR26: =ROUND( ( AQ19 + AR19 ) * AQ21 * 100, 2 ) -> 60
N27: =IF( N26 = "", "-", IFERROR( N26/M22, "-" ) ) -> 0.90434783 | Q27: =IF( Q26 = "", "-", IFERROR( Q26/P22, "-" ) ) -> -1.6777778 | T27: =IF( T26 = "", "-", IFERROR( T26/S22, "-" ) ) -> 0.055555556 | Z27: =IF( Z26 = "", "-", IFERROR( Z26/Y22, "-" ) ) -> 0.66981132 | AC27: =IF( AC26 = "", "-", IFERROR( AC26/AB22, "-" ) ) -> 0 | AF27: =IF( AF26 = "", "-", IFERROR( AF26/AE22, "-" ) ) -> 0 | AI27: =IF( AI26 = "", "-", IFERROR( AI26/AH22, "-" ) ) -> -1.375 | AL27: =IF( AL26 = "", "-", IFERROR( AL26/AK22, "-" ) ) -> 0.19753086 | AO27: =IF( AO26 = "", "-", IFERROR( AO26/AN22, "-" ) ) -> 0.066666667 | AR27: =IF( AR26 = "", "-", IFERROR( AR26/AQ22, "-" ) ) -> -0.18181818
Q28: =N26 + Q26 -> -470 | S28: Errei o Stop | T28: =Q28 + T26 -> -430 | W28: =T28 -> -430 | Z28: =T28 + Z26 -> 280 | AC28: =Z28 + AC26 -> 280 | AE28: Errei a Operação | AF28: =AC28 + AF26 -> 280 | AI28: =AF28 + AI26 -> -50 | AL28: =AI28 + AL26 -> 110 | AO28: =AL28 + AO26 -> 140 | AR28: =AO28 + AR26 -> 200
Y29: Stop Trigger | Z29: 6.6 | AB29: Stop Trigger | AC29: 2.9 | AE29: Stop Trigger | AF29: 2.6 | AH29: Stop Trigger | AI29: 2.6 | AK29: Stop Trigger | AL29: 2.6 | AN29: Stop Trigger | AQ29: Stop Trigger
Y30: Stop Limit | Z30: 6.8 | AB30: Stop Limit | AC30: 2.9 | AE30: Stop Limit | AF30: 2.85 | AH30: Stop Limit | AI30: 2.85 | AK30: Stop Limit | AL30: 2.85 | AN30: Stop Limit | AQ30: Stop Limit
AJ35: =SUM( AJ31:AJ33) -> 0
AJ36: =AJ35*200 -> 0
AJ37: -46
AJ38: =AJ36+AJ37 -> -46

Sheet CONCEITOS
A2: # | B2: Estratégia | C2: Tipo | D2: Direção | E2: Você quer que o preço... | G2: 6991 | H2: ⏳ Estimativa de Erosão do Prêmio - Iron Condor: | M2: 2.75
A3: 1 | B3: Bull Call | C3: Débito | D3: 🟢 Alta | E3: SUBA
A4: 2 | B4: Bull Put | C4: Crédito | D4: 🟢 Alta/Neutro | E4: NÃO caia | H4: Janela de Tempo (BR) | I4: Janela de Tempo (NY) | J4: % do Prêmio | L4: Valor Estimado | N4: Velocidade do Theta | O4: Descrição
A5: 3 | B5: Bear Put | C5: Débito | D5: 🔴 Queda | E5: CAIA
A6: 4 | B6: Bear Call | C6: Crédito | D6: 🔴 Queda/Neutro | E6: NÃO suba | H6: 12:30 - 13:30 | I6: 11:30 - 12:30 | J6: 0.8 | K6: 0.75 | L6: =$M$2 * J6 -> 2.2 | M6: =$M$2 * K6 -> 2.0625 | N6: Gotejamento | O6: O tempo começa a pesar, mas a volatilidade ainda segura o preço.
A7: 5 | B7: Iron Condor | C7: Crédito | D7: 🟡 Neutro | E7: FIQUE parado | H7: 13:30 - 14:30 | I7: 12:30 - 13:30 | J7: 0.7 | K7: 0.6 | L7: =$M$2 * J7 -> 1.925 | M7: =$M$2 * K7 -> 1.65 | N7: Aceleração | O7: O ponto de inflexão. O mercado começa a "aceitar" que o range vai segurar.
A8: 6 | B8: Iron Butterfly | C8: Crédito | D8: 🟡 Neutro | E8: FIQUE exatamente ali | H8: 14:30 - 16:00 | I8: 13:30 - 15:00 | J8: 0.5 | K8: 0.3 | L8: =$M$2 * J8 -> 1.375 | M8: =$M$2 * K8 -> 0.825 | N8: Cachoeira | O8: Onde a maior parte do lucro é colhida. Perda de ~$0.40 a $0.60 por hora.
A9: 7 | B9: Long Call | C9: Débito | D9: 🟢 Alta | E9: SUBA muito | H9: 16:00 - 17:00 | I9: 15:00 - 16:00 | J9: 0.2 | K9: 0 | L9: =$M$2 * J9 -> 0.55 | M9: =$M$2 * K9 -> 0 | N9: Colapso | O9: O prêmio extrínseco "vaporiza". É o lucro máximo, mas com Risco de Gamma extremo.
A10: 8 | B10: Long Put | C10: Débito | D10: 🔴 Queda | E10: CAIA muito
A11: 9 | B11: Straddle | C11: Débito | D11: ⬍ Movimento | E11: SE MOVA (qq direção) | G11: 6992 | H11: 0.54166667 | I11: 0.5 | J11: =L11/$M$2 -> 0.81818182 | L11: 2.25
A12: 10 | B12: Strangle | C12: Débito | D12: ⬍ Movimento | E12: SE MOVA muito | G12: 6997 | H12: =H11 + "00:15:00" -> 0.55208333 | I12: =H12 - "01:00:00" -> 0.51041667 | J12: =L12/$M$2 -> 0.67272727 | L12: 1.85
G13: 6995 | H13: =H12 + "00:15:00" -> 0.5625 | I13: =H13 - "01:00:00" -> 0.52083333 | J13: =L13/$M$2 -> 0.72 | L13: 1.98 | N13: superou o 7000
B15: 🧠 Macete para Nunca Confundir
B17: "BULL" = Aposta na ALTA
B18: "BEAR" = Aposta na QUEDA
B20: O segundo nome (Call/Put) = tipo de opção usada
B22: BULL CALL = Alta usando Calls → COMPRA o de baixo
B23: BULL PUT = Alta usando Puts → VENDE o de cima
B24: BEAR CALL = Baixa usando Calls → VENDE o de baixo
B25: BEAR PUT = Baixa usando Puts → COMPRA o de cima
B27: BULL → Você COMPRA o strike mais perto
B28: BEAR → Você VENDE o strike mais perto

Sheet PARÂMETROS
B2: 1. [STOP LOSS]: "Acionar recompra se o spread testado bater 1.0x o crédito. Manter o outro lado aberto." O que significa: Quando você monta um Iron Condor, você recebe um crédito financeiro total na sua conta (ex: digamos que você recebeu $1.50 no total, $0.80 do lado Put e $0.70 do lado Call). Como e quando parar a perda: Se o mercado começar a cair forte e ameaçar o seu lado Put, as opções de Put vão ficar mais caras. O playbook manda você colocar uma ordem de Stop de Recompra para o lado que está perdendo exatamente no valor do crédito total que você recebeu ($1.50). Por que não fechar tudo? É um erro comum fechar a operação inteira no susto. Se o mercado está desabando, o seu lado Call (que aposta na alta) está 100% seguro e "derretendo" a seu favor. O playbook diz para você engolir a perda do lado Put a -$1.50, mas manter o lado Call aberto até ele virar pó. Assim, o lucro residual do lado bom absorve parcialmente o tombo do lado que levou stop. 2. [TAKE PROFIT]: "Fechar o IC completo quando atingir 80% do ganho (recomprar a 20% do crédito inicial)." O que significa: O seu ganho máximo é sempre o prêmio que você recebeu, e isso só ocorre se você segurar até as opções valerem zero. Porém, o playbook provou matematicamente que tentar ganhar 100% é a pior escolha em 0DTE. A Matemática: Se você recebeu $1.50 de entrada, o seu alvo de saída é quando o IC se desvalorizar para apenas $0.30 (que representa 20% do risco original, sobrando 80% de lucro líquido). O porquê: No final do dia as opções 0DTE têm pouco valor tempo (Theta) para te dar, mas têm um risco explosivo de movimento (Gamma). Expor seu capital gigantesco só para "espremer" as últimas gotinhas (os 20% restantes do prêmio) arrisca transformar um trade quase vitorioso em perda total com uma simples notícia de fim de tarde. 3. [POWER HOUR]: "Às 14:00 ET, avaliar se consumiu > 0.5% do buffer (Range Consumed). Se sim, CLOSE." O que significa: As horas finais do SPX (Power Hour) são caóticas. O playbook usa as 14:00 (Horário de Nova York) como um "checkpoint temporal obrigatório". A Regra de Ouro: Digamos que você vendeu a perna a 1.5% de distância de queda da abertura. Se até as 14:00 o mercado já caiu e devorou 0.5% ou mais dessa sua gordura de segurança (o seu buffer), o alerta vermelho acende. As estatísticas mostram que quando o SPX consome esse pedaço do buffer até esse horário, a probabilidade da correção continuar rasgando seu strike na hora final salta para enormes 84%. A Ação: O trader não deve "ter fé" que o preço vai recuar. Se o limite de consumo for estourado até esse pino do relógio, você fecha a posição e aceita o resultado, salvando-se de uma possível catástrofe sistêmica na última hora. 4. [TIME EXIT]: Fechar tudo impreterivelmente limit order até 15:30 ET. NUNCA segurar expirando.

Sheet RESULTADOS
A1: DATA | B1: WALLET | C1: IRON C | D1: WING | E1: CONTRATOS | F1: MARGEM | G1: RETORNO | H1: RISCO MAX | I1: % WALLET | J1: RESULTADO | K1: ACUM | L1: % RESULTADO | M1: % ACERTOS | N1: TARIFA | O1: APORTE
A2: 46105 | B2: 0 | C2: - | D2: - | E2: - | F2: - | G2: - | H2: - | I2: - | J2: 0 | K2: =SUM( J$2:J2 ) -> 0 | L2: =IFERROR( SUM( J$2:J2 ) / SUM( G$2:G2 ), "-" ) -> - | M2: =IFERROR( COUNTIF( J$2:J2, ">0") / COUNTIF( C$2:C2, ">0"), "-" ) -> - | N2: 0 | O2: 20506.74
A3: =IF( WEEKDAY( A2 ) = 6, 3, 1 ) + A2 -> 46106 | B3: =B2 - N2 + O2 + J2 -> 20506.74 | C3: {=INDIRECT( ADDRESS( 19, MATCH( $A3, OPERAÇÕES!$2:$2, 0 ) + 1,,, "OPERAÇÕES" ) )} -> 5.75 | D3: {=INDIRECT( ADDRESS( 19, MATCH( $A3, OPERAÇÕES!$2:$2, 0 ),,, "OPERAÇÕES" ) )} -> 40 | E3: {=INDIRECT( ADDRESS( 21, MATCH( $A3, OPERAÇÕES!$2:$2, 0 ) + 1,,, "OPERAÇÕES" ) )} -> 2 | F3: =E3 * 100 * D3 - G3 -> 6850 | G3: =C3 * E3 * 100 -> 1150 | H3: =G3 * 2 -> 2300 | I3: =H3/B3 -> 0.11215825 | J3: {=INDIRECT( ADDRESS( 26, MATCH( $A3, OPERAÇÕES!$2:$2, 0 ) + 2,,, "OPERAÇÕES" ) )} -> 1040 | K3: =SUM( J$2:J3 ) -> 1040 | L3: =IFERROR( SUM( J$2:J3 ) / SUM( G$2:G3 ), "-" ) -> 0.90434783 | M3: =IFERROR( COUNTIF( J$2:J3, ">0") / COUNTIF( C$2:C3, ">0"), "-" ) -> 1 | N3: 19.64 | O3: 0 | R3: =20017+14064.44 -> 34081.44 | S3: =R3/70% -> 48687.771
A4: =IF( WEEKDAY( A3 ) = 6, 3, 1 ) + A3 -> 46107 | B4: =B3 - N3 + O3 + J3 -> 21527.1 | C4: {=INDIRECT( ADDRESS( 19, MATCH( $A4, OPERAÇÕES!$2:$2, 0 ) + 1,,, "OPERAÇÕES" ) )} -> 4.5 | D4: {=INDIRECT( ADDRESS( 19, MATCH( $A4, OPERAÇÕES!$2:$2, 0 ),,, "OPERAÇÕES" ) )} -> 45 | E4: {=INDIRECT( ADDRESS( 21, MATCH( $A4, OPERAÇÕES!$2:$2, 0 ) + 1,,, "OPERAÇÕES" ) )} -> 2 | F4: =E4 * 100 * D4 - G4 -> 8100 | G4: =C4 * E4 * 100 -> 900 | H4: =G4 * 2 -> 1800 | I4: =H4/B4 -> 0.083615536 | J4: {=INDIRECT( ADDRESS( 26, MATCH( $A4, OPERAÇÕES!$2:$2, 0 ) + 2,,, "OPERAÇÕES" ) )} -> -1510 | K4: =SUM( J$2:J4 ) -> -470 | L4: =IFERROR( SUM( J$2:J4 ) / SUM( G$2:G4 ), "-" ) -> -0.22926829 | M4: =IFERROR( COUNTIF( J$2:J4, ">0") / COUNTIF( C$2:C4, ">0"), "-" ) -> 0.5 | N4: 16.67 | O4: 0 | R4: 5.2069 | S4: 5.2069
A5: =IF( WEEKDAY( A4 ) = 6, 3, 1 ) + A4 -> 46108 | B5: =B4 - N4 + O4 + J4 -> 20000.43 | C5: {=INDIRECT( ADDRESS( 19, MATCH( $A5, OPERAÇÕES!$2:$2, 0 ) + 1,,, "OPERAÇÕES" ) )} -> 3.6 | D5: {=INDIRECT( ADDRESS( 19, MATCH( $A5, OPERAÇÕES!$2:$2, 0 ),,, "OPERAÇÕES" ) )} -> 40 | E5: {=INDIRECT( ADDRESS( 21, MATCH( $A5, OPERAÇÕES!$2:$2, 0 ) + 1,,, "OPERAÇÕES" ) )} -> 2 | F5: =E5 * 100 * D5 - G5 -> 7280 | G5: =C5 * E5 * 100 -> 720 | H5: =G5 * 2 -> 1440 | I5: =H5/B5 -> 0.071998452 | J5: {=INDIRECT( ADDRESS( 26, MATCH( $A5, OPERAÇÕES!$2:$2, 0 ) + 2,,, "OPERAÇÕES" ) )} -> 40 | K5: =SUM( J$2:J5 ) -> -430 | L5: =IFERROR( SUM( J$2:J5 ) / SUM( G$2:G5 ), "-" ) -> -0.15523466 | M5: =IFERROR( COUNTIF( J$2:J5, ">0") / COUNTIF( C$2:C5, ">0"), "-" ) -> 0.66666667 | N5: 19.61 | O5: 0 | R5: =ROUND( R3/R4, 2 ) -> 6545.44 | S5: =ROUND( S3/S4, 2 ) -> 9350.63
A6: =IF( WEEKDAY( A5 ) = 6, 3, 1 ) + A5 -> 46111 | B6: =B5 - N5 + O5 + J5 -> 20020.82 | C6: - | D6: - | E6: - | F6: - | G6: - | H6: - | I6: - | J6: 0 | K6: 0 | L6: =IFERROR( SUM( J$2:J6 ) / SUM( G$2:G6 ), "-" ) -> -0.15523466 | M6: =IFERROR( COUNTIF( J$2:J6, ">0") / COUNTIF( C$2:C6, ">0"), "-" ) -> 0.66666667 | N6: 0 | O6: 7030.41 | R6: 700 | S6: 1100
A7: =IF( WEEKDAY( A6 ) = 6, 3, 1 ) + A6 -> 46112 | B7: =B6 - N6 + O6 + J6 -> 27051.23 | C7: - | D7: - | E7: - | F7: - | G7: - | H7: - | I7: - | J7: 0 | K7: 0 | L7: =IFERROR( SUM( J$2:J7 ) / SUM( G$2:G7 ), "-" ) -> -0.15523466 | M7: =IFERROR( COUNTIF( J$2:J7, ">0") / COUNTIF( C$2:C7, ">0"), "-" ) -> 0.66666667 | N7: 0 | O7: 0 | R7: =R5/R6 -> 9.3506286 | S7: =S5/S6 -> 8.5005727
A8: =IF( WEEKDAY( A7 ) = 6, 3, 1 ) + A7 -> 46113 | B8: =B7 - N7 + O7 + J7 -> 27051.23 | C8: - | D8: - | E8: - | F8: - | G8: - | H8: - | I8: - | J8: 0 | K8: 0 | L8: =IFERROR( SUM( J$2:J8 ) / SUM( G$2:G8 ), "-" ) -> -0.15523466 | M8: =IFERROR( COUNTIF( J$2:J8, ">0") / COUNTIF( C$2:C8, ">0"), "-" ) -> 0.66666667 | N8: 0 | O8: 0
A9: =IF( WEEKDAY( A8 ) = 6, 3, 1 ) + A8 -> 46114 | B9: =B8 - N8 + O8 + J8 -> 27051.23 | C9: - | D9: - | E9: - | F9: - | G9: - | H9: - | I9: - | J9: 0 | K9: 0 | L9: =IFERROR( SUM( J$2:J9 ) / SUM( G$2:G9 ), "-" ) -> -0.15523466 | M9: =IFERROR( COUNTIF( J$2:J9, ">0") / COUNTIF( C$2:C9, ">0"), "-" ) -> 0.66666667 | N9: 0 | O9: 0
A10: =IF( WEEKDAY( A9 ) = 6, 3, 1 ) + A9 -> 46115 | B10: =B9 - N9 + O9 + J9 -> 27051.23 | C10: - | D10: - | E10: - | F10: - | G10: - | H10: - | I10: - | J10: 0 | K10: 0 | L10: =IFERROR( SUM( J$2:J10 ) / SUM( G$2:G10 ), "-" ) -> -0.15523466 | M10: =IFERROR( COUNTIF( J$2:J10, ">0") / COUNTIF( C$2:C10, ">0"), "-" ) -> 0.66666667 | N10: 0 | O10: 983.35
A11: =IF( WEEKDAY( A10 ) = 6, 3, 1 ) + A10 -> 46118 | B11: =B10 - N10 + O10 + J10 -> 28034.58 | C11: - | D11: - | E11: - | F11: - | G11: - | H11: - | I11: - | J11: 0 | K11: 0 | L11: =IFERROR( SUM( J$2:J11 ) / SUM( G$2:G11 ), "-" ) -> -0.15523466 | M11: =IFERROR( COUNTIF( J$2:J11, ">0") / COUNTIF( C$2:C11, ">0"), "-" ) -> 0.66666667 | N11: 0 | O11: 0 | R11: DATA | S11: APORTES | T11: WALLET EOP | U11: % | V11: Dias TOTAL | W11: Dias WIN | X11: Dias LOST | Y11: % WIN | Z11: % LOST | AA11: CONTRATOS | AB11: P/L TOTAL | AC11: P/L ⨱ WIN | AD11: P/L ⨱ LOST | AE11: POTENCIAL | AF11: P/L Médio | AG11: Dias
A12: =IF( WEEKDAY( A11 ) = 6, 3, 1 ) + A11 -> 46119 | B12: =B11 - N11 + O11 + J11 -> 28034.58 | C12: {=INDIRECT( ADDRESS( 19, MATCH( $A12, OPERAÇÕES!$2:$2, 0 ) + 1,,, "OPERAÇÕES" ) )} -> 5.3 | D12: {=INDIRECT( ADDRESS( 19, MATCH( $A12, OPERAÇÕES!$2:$2, 0 ),,, "OPERAÇÕES" ) )} -> 40 | E12: {=INDIRECT( ADDRESS( 21, MATCH( $A12, OPERAÇÕES!$2:$2, 0 ) + 1,,, "OPERAÇÕES" ) )} -> 2 | F12: =E12 * 100 * D12 - G12 -> 6940 | G12: =C12 * E12 * 100 -> 1060 | H12: =G12 * 2 -> 2120 | I12: =H12/B12 -> 0.075620894 | J12: {=INDIRECT( ADDRESS( 26, MATCH( $A12, OPERAÇÕES!$2:$2, 0 ) + 2,,, "OPERAÇÕES" ) )} -> 710 | K12: =SUM( J$2:J12 ) -> 280 | L12: =IFERROR( SUM( J$2:J12 ) / SUM( G$2:G12 ), "-" ) -> 0.07310705 | M12: =IFERROR( COUNTIF( J$2:J12, ">0") / COUNTIF( C$2:C12, ">0"), "-" ) -> 0.75 | N12: 19.64 | O12: 0 | R12: 46082 | S12: =SUMIFS( Table2[[#All],[APORTE]], Table2[[#All],[DATA]], "<" & DATE( YEAR( $R12 + 32 ), MONTH( $R12 + 32 ), 1 ) ) -> 27537.15 | T12: =IF( _xlfn.MAXIFS( Table2[[#All],[DATA]], Table2[[#All],[DATA]], ">="& $R12, Table2[[#All],[DATA]], "<" & DATE( YEAR( $R12 + 32 ), MONTH( $R12 + 32 ), 1 ) ) > 0, VLOOKUP( _xlfn.MAXIFS( Table2[[#All],[DATA]], Table2[[#All],[DATA]], ">="& $R12, Table2[[#All],[DATA]], "<" & DATE( YEAR( $R12 + 32 ), MONTH( $R12 + 32 ), 1 ) ), Table2[#All], MATCH( "WALLET", Table2[#Headers], 0 ), 0 ), "-" ) -> 27051.23 | U12: =IFERROR( IF( T12 = 0, "-", T12/ S12 - 1 ), "-" ) -> -0.01764598 | V12: =COUNTIFS( Table2[[#All],[CONTRATOS]], ">"& 0, Table2[[#All],[DATA]], ">="& $R12, Table2[[#All],[DATA]], "<" & DATE( YEAR( $R12 + 32 ), MONTH( $R12 + 32 ), 1 ) ) -> 3 | W12: =COUNTIFS( Table2[[#All],[CONTRATOS]], ">"& 0, Table2[[#All],[DATA]], ">="& $R12, Table2[[#All],[DATA]], "<" & DATE( YEAR( $R12 + 32 ), MONTH( $R12 + 32 ), 1 ), Table2[[#All],[RESULTADO]], ">" & 0 ) -> 2 | X12: =COUNTIFS( Table2[[#All],[CONTRATOS]], ">"& 0, Table2[[#All],[DATA]], ">="& $R12, Table2[[#All],[DATA]], "<" & DATE( YEAR( $R12 + 32 ), MONTH( $R12 + 32 ), 1 ), Table2[[#All],[RESULTADO]], "<" & 0 ) -> 1 | Y12: =IFERROR( W12 / $V12, "-" ) -> 0.66666667 | Z12: =IFERROR( X12 / $V12, "-" ) -> 0.33333333 | AA12: =SUMIFS( Table2[[#All],[CONTRATOS]], Table2[[#All],[DATA]], ">="& $R12, Table2[[#All],[DATA]], "<" & DATE( YEAR( $R12 + 32 ), MONTH( $R12 + 32 ), 1 ) ) -> 6 | AB12: =SUMIFS( Table2[[#All],[RESULTADO]], Table2[[#All],[DATA]], ">="& $R12, Table2[[#All],[DATA]], "<" & DATE( YEAR( $R12 + 32 ), MONTH( $R12 + 32 ), 1 ) ) -> -430 | AC12: =SUMIFS( Table2[[#All],[RESULTADO]], Table2[[#All],[DATA]], ">="& $R12, Table2[[#All],[DATA]], "<" & DATE( YEAR( $R12 + 32 ), MONTH( $R12 + 32 ), 1 ), Table2[[#All],[RESULTADO]], ">" & 0 ) / W12 -> 540 | AD12: =IFERROR( SUMIFS( Table2[[#All],[RESULTADO]], Table2[[#All],[DATA]], ">="& $R12, Table2[[#All],[DATA]], "<" & DATE( YEAR( $R12 + 32 ), MONTH( $R12 + 32 ), 1 ), Table2[[#All],[RESULTADO]], "<" & 0 ) / X12, "-" ) -> -1510 | AE12: =IFERROR( SUMPRODUCT( Y12:Z12, AC12:AD12 ), "-" ) -> -143.33333 | AF12: =IFERROR( AB12/V12, "-" ) -> -143.33333 | AG12: =IFERROR( IF( $R$5 / AF12 <= 0, "+99", $R$5 / AF12 ), "-" ) -> +99
A13: =IF( WEEKDAY( A12 ) = 6, 3, 1 ) + A12 -> 46120 | B13: =B12 - N12 + O12 + J12 -> 28724.94 | C13: {=INDIRECT( ADDRESS( 19, MATCH( $A13, OPERAÇÕES!$2:$2, 0 ) + 1,,, "OPERAÇÕES" ) )} -> 2.9 | D13: {=INDIRECT( ADDRESS( 19, MATCH( $A13, OPERAÇÕES!$2:$2, 0 ),,, "OPERAÇÕES" ) )} -> 40 | E13: {=INDIRECT( ADDRESS( 21, MATCH( $A13, OPERAÇÕES!$2:$2, 0 ) + 1,,, "OPERAÇÕES" ) )} -> 2 | F13: =E13 * 100 * D13 - G13 -> 7420 | G13: =C13 * E13 * 100 -> 580 | H13: =G13 * 2 -> 1160 | I13: =H13/B13 -> 0.040383026 | J13: {=INDIRECT( ADDRESS( 26, MATCH( $A13, OPERAÇÕES!$2:$2, 0 ) + 2,,, "OPERAÇÕES" ) )} -> 0 | K13: =SUM( J$2:J13 ) -> 280 | L13: =IFERROR( SUM( J$2:J13 ) / SUM( G$2:G13 ), "-" ) -> 0.063492063 | M13: =IFERROR( COUNTIF( J$2:J13, ">0") / COUNTIF( C$2:C13, ">0"), "-" ) -> 0.6 | N13: =28720.03 - 28710.24 -> 9.79 | O13: 0 | R13: =DATE( YEAR( R12 + 32 ), MONTH( R12 + 32 ), 1 ) -> 46113 | S13: =SUMIFS( Table2[[#All],[APORTE]], Table2[[#All],[DATA]], "<" & DATE( YEAR( $R13 + 32 ), MONTH( $R13 + 32 ), 1 ) ) -> 28520.5 | T13: =IF( _xlfn.MAXIFS( Table2[[#All],[DATA]], Table2[[#All],[DATA]], ">="& $R13, Table2[[#All],[DATA]], "<" & DATE( YEAR( $R13 + 32 ), MONTH( $R13 + 32 ), 1 ) ) > 0, VLOOKUP( _xlfn.MAXIFS( Table2[[#All],[DATA]], Table2[[#All],[DATA]], ">="& $R13, Table2[[#All],[DATA]], "<" & DATE( YEAR( $R13 + 32 ), MONTH( $R13 + 32 ), 1 ) ), Table2[#All], MATCH( "WALLET", Table2[#Headers], 0 ), 0 ), "-" ) -> 28666.19 | U13: =IFERROR( IF( T13 = 0, "-", T13/ S13 - 1 ), "-" ) -> 0.0051082555 | V13: =COUNTIFS( Table2[[#All],[CONTRATOS]], ">"& 0, Table2[[#All],[DATA]], ">="& $R13, Table2[[#All],[DATA]], "<" & DATE( YEAR( $R13 + 32 ), MONTH( $R13 + 32 ), 1 ) ) -> 3 | W13: =COUNTIFS( Table2[[#All],[CONTRATOS]], ">"& 0, Table2[[#All],[DATA]], ">="& $R13, Table2[[#All],[DATA]], "<" & DATE( YEAR( $R13 + 32 ), MONTH( $R13 + 32 ), 1 ), Table2[[#All],[RESULTADO]], ">" & 0 ) -> 1 | X13: =COUNTIFS( Table2[[#All],[CONTRATOS]], ">"& 0, Table2[[#All],[DATA]], ">="& $R13, Table2[[#All],[DATA]], "<" & DATE( YEAR( $R13 + 32 ), MONTH( $R13 + 32 ), 1 ), Table2[[#All],[RESULTADO]], "<" & 0 ) -> 0 | Y13: =IFERROR( W13 / $V13, "-" ) -> 0.33333333 | Z13: =IFERROR( X13 / $V13, "-" ) -> 0 | AA13: =SUMIFS( Table2[[#All],[CONTRATOS]], Table2[[#All],[DATA]], ">="& $R13, Table2[[#All],[DATA]], "<" & DATE( YEAR( $R13 + 32 ), MONTH( $R13 + 32 ), 1 ) ) -> 6 | AB13: =SUMIFS( Table2[[#All],[RESULTADO]], Table2[[#All],[DATA]], ">="& $R13, Table2[[#All],[DATA]], "<" & DATE( YEAR( $R13 + 32 ), MONTH( $R13 + 32 ), 1 ) ) -> 710 | AC13: =SUMIFS( Table2[[#All],[RESULTADO]], Table2[[#All],[DATA]], ">="& $R13, Table2[[#All],[DATA]], "<" & DATE( YEAR( $R13 + 32 ), MONTH( $R13 + 32 ), 1 ), Table2[[#All],[RESULTADO]], ">" & 0 ) / W13 -> 710 | AD13: =IFERROR( SUMIFS( Table2[[#All],[RESULTADO]], Table2[[#All],[DATA]], ">="& $R13, Table2[[#All],[DATA]], "<" & DATE( YEAR( $R13 + 32 ), MONTH( $R13 + 32 ), 1 ), Table2[[#All],[RESULTADO]], "<" & 0 ) / X13, "-" ) -> - | AE13: =IFERROR( SUMPRODUCT( Y13:Z13, AC13:AD13 ), "-" ) -> 236.66667 | AF13: =IFERROR( AB13/V13, "-" ) -> 236.66667 | AG13: =IFERROR( IF( $R$5 / AF13 <= 0, "+99", $R$5 / AF13 ), "-" ) -> 27.656789
A14: =IF( WEEKDAY( A13 ) = 6, 3, 1 ) + A13 -> 46121 | B14: =B13 - N13 + O13 + J13 -> 28715.15 | C14: {=INDIRECT( ADDRESS( 19, MATCH( $A14, OPERAÇÕES!$2:$2, 0 ) + 1,,, "OPERAÇÕES" ) )} -> 2.85 | D14: {=INDIRECT( ADDRESS( 19, MATCH( $A14, OPERAÇÕES!$2:$2, 0 ),,, "OPERAÇÕES" ) )} -> 55 | E14: {=INDIRECT( ADDRESS( 21, MATCH( $A14, OPERAÇÕES!$2:$2, 0 ) + 1,,, "OPERAÇÕES" ) )} -> 2 | F14: =E14 * 100 * D14 - G14 -> 10430 | G14: =C14 * E14 * 100 -> 570 | H14: =G14 * 2 -> 1140 | I14: =H14/B14 -> 0.039700298 | J14: {=INDIRECT( ADDRESS( 26, MATCH( $A14, OPERAÇÕES!$2:$2, 0 ) + 2,,, "OPERAÇÕES" ) )} -> 0 | K14: =SUM( J$2:J14 ) -> 280 | L14: =IFERROR( SUM( J$2:J14 ) / SUM( G$2:G14 ), "-" ) -> 0.0562249 | M14: =IFERROR( COUNTIF( J$2:J14, ">0") / COUNTIF( C$2:C14, ">0"), "-" ) -> 0.5 | N14: 48.96 | O14: 0 | R14: =DATE( YEAR( R13 + 32 ), MONTH( R13 + 32 ), 1 ) -> 46143
A15: =IF( WEEKDAY( A14 ) = 6, 3, 1 ) + A14 -> 46122 | B15: =B14 - N14 + O14 + J14 -> 28666.19 | R15: =DATE( YEAR( R14 + 32 ), MONTH( R14 + 32 ), 1 ) -> 46174
R16: =DATE( YEAR( R15 + 32 ), MONTH( R15 + 32 ), 1 ) -> 46204
R17: =DATE( YEAR( R16 + 32 ), MONTH( R16 + 32 ), 1 ) -> 46235
R18: =DATE( YEAR( R17 + 32 ), MONTH( R17 + 32 ), 1 ) -> 46266
R19: =DATE( YEAR( R18 + 32 ), MONTH( R18 + 32 ), 1 ) -> 46296
R20: =DATE( YEAR( R19 + 32 ), MONTH( R19 + 32 ), 1 ) -> 46327
R21: =DATE( YEAR( R20 + 32 ), MONTH( R20 + 32 ), 1 ) -> 46357
R22: =DATE( YEAR( R21 + 32 ), MONTH( R21 + 32 ), 1 ) -> 46388
R23: =DATE( YEAR( R22 + 32 ), MONTH( R22 + 32 ), 1 ) -> 46419
R24: =DATE( YEAR( R23 + 32 ), MONTH( R23 + 32 ), 1 ) -> 46447
D30: 0.72 | E30: 4
D31: 1.45 | E31: 1
D32: 1.46 | E32: 1
E33: =SUMPRODUCT( D30:D32, E30:E32 ) -> 5.79

Sheet tastytrade_transactions_history
A1: Date/Time | B1: Date | C1: Time | D1: Type | E1: Sub Type | F1: Action | G1: Symbol | H1: Instrument Type | I1: Description | J1: Total | K1: Value | L1: Quantity | M1: Average Price | N1: Commissions | O1: Fees | P1: Multiplier | Q1: Root Symbol | R1: Underlying Symbol | S1: Expiration Date | T1: Strike Price | U1: Call or Put | V1: Order # | W1: Currency
A2: 46136.67 | B2: 46136 | C2: 0.67046296 | D2: Trade | E2: Buy to Close | F2: BUY_TO_CLOSE | G2: SPXW 260424C07140000 | H2: Equity Option | I2: Bought 1 SPX 04/24/26 Call 7140.00 @ 21.35 | J2: -2135.72 | K2: -2135 | L2: 1 | M2: -2135 | N2: 0 | O2: -0.72 | P2: 100 | Q2: SPXW | R2: SPX | S2: 46136 | T2: 7140 | U2: CALL | V2: 459569399 | W2: USD
A3: 46136.67 | B3: 46136 | C3: 0.67046296 | D3: Trade | E3: Sell to Close | F3: SELL_TO_CLOSE | G3: SPXW 260424C07135000 | H3: Equity Option | I3: Sold 1 SPX 04/24/26 Call 7135.00 @ 26.20 | J3: 2619.28 | K3: 2620 | L3: 1 | M3: 2620 | N3: 0 | O3: -0.72 | P3: 100 | Q3: SPXW | R3: SPX | S3: 46136 | T3: 7135 | U3: CALL | V3: 459569399 | W3: USD
A4: 46136.67 | B4: 46136 | C4: 0.67046296 | D4: Trade | E4: Buy to Close | F4: BUY_TO_CLOSE | G4: SPXW 260424C07140000 | H4: Equity Option | I4: Bought 1 SPX 04/24/26 Call 7140.00 @ 21.35 | J4: -2135.72 | K4: -2135 | L4: 1 | M4: -2135 | N4: 0 | O4: -0.72 | P4: 100 | Q4: SPXW | R4: SPX | S4: 46136 | T4: 7140 | U4: CALL | V4: 459569399 | W4: USD
A5: 46136.67 | B5: 46136 | C5: 0.67046296 | D5: Trade | E5: Sell to Close | F5: SELL_TO_CLOSE | G5: SPXW 260424C07135000 | H5: Equity Option | I5: Sold 1 SPX 04/24/26 Call 7135.00 @ 26.20 | J5: 2619.28 | K5: 2620 | L5: 1 | M5: 2620 | N5: 0 | O5: -0.72 | P5: 100 | Q5: SPXW | R5: SPX | S5: 46136 | T5: 7135 | U5: CALL | V5: 459569399 | W5: USD
A6: 46136.454 | B6: 46136 | C6: 0.45440972 | D6: Trade | E6: Sell to Open | F6: SELL_TO_OPEN | G6: SPXW 260424C07140000 | H6: Equity Option | I6: Sold 2 SPX 04/24/26 Call 7140.00 @ 6.51 | J6: 1298.54 | K6: 1302 | L6: 2 | M6: 651 | N6: -2 | O6: -1.46 | P6: 100 | Q6: SPXW | R6: SPX | S6: 46136 | T6: 7140 | U6: CALL | V6: 458835898 | W6: USD
A7: 46136.454 | B7: 46136 | C7: 0.45440972 | D7: Trade | E7: Buy to Open | F7: BUY_TO_OPEN | G7: SPXW 260424C07135000 | H7: Equity Option | I7: Bought 2 SPX 04/24/26 Call 7135.00 @ 8.26 | J7: -1655.45 | K7: -1652 | L7: 2 | M7: -826 | N7: -2 | O7: -1.45 | P7: 100 | Q7: SPXW | R7: SPX | S7: 46136 | T7: 7135 | U7: CALL | V7: 458835898 | W7: USD
A8: 46130.684 | B8: 46130 | C8: 0.68368056 | D8: Money Movement | E8: Balance Adjustment | I8: Regulatory fee adjustment | J8: 0.06 | K8: 0.06 | L8: 0 | N8: 0 | O8: 0 | W8: USD
A9: 46129.68 | B9: 46129 | C9: 0.68016204 | D9: Trade | E9: Buy to Close | F9: BUY_TO_CLOSE | G9: SPXW 260417C07140000 | H9: Equity Option | I9: Bought 2 SPX 04/17/26 Call 7140.00 @ 0.27 | J9: -55.45 | K9: -54 | L9: 2 | M9: -27 | N9: 0 | O9: -1.45 | P9: 100 | Q9: SPXW | R9: SPX | S9: 46129 | T9: 7140 | U9: CALL | V9: 455755390 | W9: USD
A10: 46129.68 | B10: 46129 | C10: 0.68016204 | D10: Trade | E10: Sell to Close | F10: SELL_TO_CLOSE | G10: SPXW 260417C07135000 | H10: Equity Option | I10: Sold 2 SPX 04/17/26 Call 7135.00 @ 0.47 | J10: 92.54 | K10: 94 | L10: 2 | M10: 47 | N10: 0 | O10: -1.46 | P10: 100 | Q10: SPXW | R10: SPX | S10: 46129 | T10: 7135 | U10: CALL | V10: 455755390 | W10: USD
A11: 46129.599 | B11: 46129 | C11: 0.59928241 | D11: Trade | E11: Sell to Open | F11: SELL_TO_OPEN | G11: SPXW 260417C07140000 | H11: Equity Option | I11: Sold 1 SPX 04/17/26 Call 7140.00 @ 4.63 | J11: 461.28 | K11: 463 | L11: 1 | M11: 463 | N11: -1 | O11: -0.72 | P11: 100 | Q11: SPXW | R11: SPX | S11: 46129 | T11: 7140 | U11: CALL | V11: 455644177 | W11: USD
A12: 46129.599 | B12: 46129 | C12: 0.59928241 | D12: Trade | E12: Buy to Open | F12: BUY_TO_OPEN | G12: SPXW 260417C07135000 | H12: Equity Option | I12: Bought 1 SPX 04/17/26 Call 7135.00 @ 6.63 | J12: -664.72 | K12: -663 | L12: 1 | M12: -663 | N12: -1 | O12: -0.72 | P12: 100 | Q12: SPXW | R12: SPX | S12: 46129 | T12: 7135 | U12: CALL | V12: 455644177 | W12: USD
A13: 46129.599 | B13: 46129 | C13: 0.59928241 | D13: Trade | E13: Sell to Open | F13: SELL_TO_OPEN | G13: SPXW 260417C07140000 | H13: Equity Option | I13: Sold 1 SPX 04/17/26 Call 7140.00 @ 4.63 | J13: 461.28 | K13: 463 | L13: 1 | M13: 463 | N13: -1 | O13: -0.72 | P13: 100 | Q13: SPXW | R13: SPX | S13: 46129 | T13: 7140 | U13: CALL | V13: 455644177 | W13: USD
A14: 46129.599 | B14: 46129 | C14: 0.59928241 | D14: Trade | E14: Buy to Open | F14: BUY_TO_OPEN | G14: SPXW 260417C07135000 | H14: Equity Option | I14: Bought 1 SPX 04/17/26 Call 7135.00 @ 6.63 | J14: -664.72 | K14: -663 | L14: 1 | M14: -663 | N14: -1 | O14: -0.72 | P14: 100 | Q14: SPXW | R14: SPX | S14: 46129 | T14: 7135 | U14: CALL | V14: 455644177 | W14: USD
A15: 46129.563 | B15: 46129 | C15: 0.56300926 | D15: Trade | E15: Buy to Close | F15: BUY_TO_CLOSE | G15: SPXW 260417C07100000 | H15: Equity Option | I15: Bought 1 SPX 04/17/26 Call 7100.00 @ 43.00 | J15: -4300.72 | K15: -4300 | L15: 1 | M15: -4300 | N15: 0 | O15: -0.72 | P15: 100 | Q15: SPXW | R15: SPX | S15: 46129 | T15: 7100 | U15: CALL | V15: 455423841 | W15: USD
A16: 46129.563 | B16: 46129 | C16: 0.56300926 | D16: Trade | E16: Sell to Close | F16: SELL_TO_CLOSE | G16: SPXW 260417C07095000 | H16: Equity Option | I16: Sold 1 SPX 04/17/26 Call 7095.00 @ 47.80 | J16: 4779.28 | K16: 4780 | L16: 1 | M16: 4780 | N16: 0 | O16: -0.72 | P16: 100 | Q16: SPXW | R16: SPX | S16: 46129 | T16: 7095 | U16: CALL | V16: 455423841 | W16: USD
A17: 46129.44 | B17: 46129 | C17: 0.43972222 | D17: Trade | E17: Sell to Open | F17: SELL_TO_OPEN | G17: SPXW 260417C07100000 | H17: Equity Option | I17: Sold 1 SPX 04/17/26 Call 7100.00 @ 10.34 | J17: 1032.28 | K17: 1034 | L17: 1 | M17: 1034 | N17: -1 | O17: -0.72 | P17: 100 | Q17: SPXW | R17: SPX | S17: 46129 | T17: 7100 | U17: CALL | V17: 455309658 | W17: USD
A18: 46129.44 | B18: 46129 | C18: 0.43972222 | D18: Trade | E18: Buy to Open | F18: BUY_TO_OPEN | G18: SPXW 260417C07095000 | H18: Equity Option | I18: Bought 1 SPX 04/17/26 Call 7095.00 @ 12.69 | J18: -1270.72 | K18: -1269 | L18: 1 | M18: -1269 | N18: -1 | O18: -0.72 | P18: 100 | Q18: SPXW | R18: SPX | S18: 46129 | T18: 7095 | U18: CALL | V18: 455309658 | W18: USD
A19: 46128.572 | B19: 46128 | C19: 0.57173611 | D19: Money Movement | E19: Withdrawal | I19: Digital Asset Fund Conversion Withdrawal of 49.47 USDC/USD | J19: -50 | K19: -50 | L19: 0 | N19: 0 | O19: 0 | W19: USD
A20: 46127.579 | B20: 46127 | C20: 0.57861111 | D20: Trade | E20: Sell to Close | F20: SELL_TO_CLOSE | G20: SPXW 260415C07060000 | H20: Equity Option | I20: Sold 1 SPX 04/15/26 Call 7060.00 @ 0.12 | J20: 11.28 | K20: 12 | L20: 1 | M20: 12 | N20: 0 | O20: -0.72 | P20: 100 | Q20: SPXW | R20: SPX | S20: 46127 | T20: 7060 | U20: CALL | V20: 454655076 | W20: USD
A21: 46127.579 | B21: 46127 | C21: 0.57861111 | D21: Trade | E21: Buy to Close | F21: BUY_TO_CLOSE | G21: SPXW 260415C07020000 | H21: Equity Option | I21: Bought 1 SPX 04/15/26 Call 7020.00 @ 0.67 | J21: -67.72 | K21: -67 | L21: 1 | M21: -67 | N21: 0 | O21: -0.72 | P21: 100 | Q21: SPXW | R21: SPX | S21: 46127 | T21: 7020 | U21: CALL | V21: 454655076 | W21: USD
A22: 46127.579 | B22: 46127 | C22: 0.57861111 | D22: Trade | E22: Sell to Close | F22: SELL_TO_CLOSE | G22: SPXW 260415C07060000 | H22: Equity Option | I22: Sold 1 SPX 04/15/26 Call 7060.00 @ 0.12 | J22: 11.28 | K22: 12 | L22: 1 | M22: 12 | N22: 0 | O22: -0.72 | P22: 100 | Q22: SPXW | R22: SPX | S22: 46127 | T22: 7060 | U22: CALL | V22: 454655076 | W22: USD
A23: 46127.579 | B23: 46127 | C23: 0.57861111 | D23: Trade | E23: Buy to Close | F23: BUY_TO_CLOSE | G23: SPXW 260415C07020000 | H23: Equity Option | I23: Bought 1 SPX 04/15/26 Call 7020.00 @ 0.67 | J23: -67.72 | K23: -67 | L23: 1 | M23: -67 | N23: 0 | O23: -0.72 | P23: 100 | Q23: SPXW | R23: SPX | S23: 46127 | T23: 7020 | U23: CALL | V23: 454655076 | W23: USD
A24: 46127.575 | B24: 46127 | C24: 0.5747338 | D24: Trade | E24: Sell to Close | F24: SELL_TO_CLOSE | G24: SPXW 260415P06920000 | H24: Equity Option | I24: Sold 1 SPX 04/15/26 Put 6920.00 @ 1.30 | J24: 129.28 | K24: 130 | L24: 1 | M24: 130 | N24: 0 | O24: -0.72 | P24: 100 | Q24: SPXW | R24: SPX | S24: 46127 | T24: 6920 | U24: PUT | V24: 454558051 | W24: USD
A25: 46127.575 | B25: 46127 | C25: 0.5747338 | D25: Trade | E25: Buy to Close | F25: BUY_TO_CLOSE | G25: SPXW 260415P06960000 | H25: Equity Option | I25: Bought 1 SPX 04/15/26 Put 6960.00 @ 3.75 | J25: -375.72 | K25: -375 | L25: 1 | M25: -375 | N25: 0 | O25: -0.72 | P25: 100 | Q25: SPXW | R25: SPX | S25: 46127 | T25: 6960 | U25: PUT | V25: 454558051 | W25: USD
A26: 46127.575 | B26: 46127 | C26: 0.5747338 | D26: Trade | E26: Sell to Close | F26: SELL_TO_CLOSE | G26: SPXW 260415P06920000 | H26: Equity Option | I26: Sold 1 SPX 04/15/26 Put 6920.00 @ 1.30 | J26: 129.28 | K26: 130 | L26: 1 | M26: 130 | N26: 0 | O26: -0.72 | P26: 100 | Q26: SPXW | R26: SPX | S26: 46127 | T26: 6920 | U26: PUT | V26: 454558051 | W26: USD
A27: 46127.575 | B27: 46127 | C27: 0.5747338 | D27: Trade | E27: Buy to Close | F27: BUY_TO_CLOSE | G27: SPXW 260415P06960000 | H27: Equity Option | I27: Bought 1 SPX 04/15/26 Put 6960.00 @ 3.75 | J27: -375.72 | K27: -375 | L27: 1 | M27: -375 | N27: 0 | O27: -0.72 | P27: 100 | Q27: SPXW | R27: SPX | S27: 46127 | T27: 6960 | U27: PUT | V27: 454558051 | W27: USD
A28: 46127.494 | B28: 46127 | C28: 0.49414352 | D28: Trade | E28: Buy to Open | F28: BUY_TO_OPEN | G28: SPXW 260415P06920000 | H28: Equity Option | I28: Bought 2 SPX 04/15/26 Put 6920.00 @ 0.82 | J28: -167.45 | K28: -164 | L28: 2 | M28: -82 | N28: -2 | O28: -1.45 | P28: 100 | Q28: SPXW | R28: SPX | S28: 46127 | T28: 6920 | U28: PUT | V28: 454551885 | W28: USD
A29: 46127.494 | B29: 46127 | C29: 0.49414352 | D29: Trade | E29: Buy to Open | F29: BUY_TO_OPEN | G29: SPXW 260415C07060000 | H29: Equity Option | I29: Bought 2 SPX 04/15/26 Call 7060.00 @ 0.28 | J29: -59.45 | K29: -56 | L29: 2 | M29: -28 | N29: -2 | O29: -1.45 | P29: 100 | Q29: SPXW | R29: SPX | S29: 46127 | T29: 7060 | U29: CALL | V29: 454551885 | W29: USD
A30: 46127.494 | B30: 46127 | C30: 0.49414352 | D30: Trade | E30: Sell to Open | F30: SELL_TO_OPEN | G30: SPXW 260415P06960000 | H30: Equity Option | I30: Sold 2 SPX 04/15/26 Put 6960.00 @ 2.35 | J30: 466.54 | K30: 470 | L30: 2 | M30: 235 | N30: -2 | O30: -1.46 | P30: 100 | Q30: SPXW | R30: SPX | S30: 46127 | T30: 6960 | U30: PUT | V30: 454551885 | W30: USD
A31: 46127.494 | B31: 46127 | C31: 0.49414352 | D31: Trade | E31: Sell to Open | F31: SELL_TO_OPEN | G31: SPXW 260415C07020000 | H31: Equity Option | I31: Sold 2 SPX 04/15/26 Call 7020.00 @ 1.50 | J31: 296.54 | K31: 300 | L31: 2 | M31: 150 | N31: -2 | O31: -1.46 | P31: 100 | Q31: SPXW | R31: SPX | S31: 46127 | T31: 7020 | U31: CALL | V31: 454551885 | W31: USD
... A43: 46126.48 | B43: 46126 | C43: 0.47981481 | D43: Trade | E43: Sell to Open | F43: SELL_TO_OPEN | G43: SPXW 260414C06950000 | H43: Equity Option | I43: Sold 1 SPX 04/14/26 Call 6950.00 @ 3.95 | J43: 393.28 | K43: 395 | L43: 1 | M43: 395 | N43: -1 | O43: -0.72 | P43: 100 | Q43: SPXW | R43: SPX | S43: 46126 | T43: 6950 | U43: CALL | V43: 454131070 | W43: USD
A44: 46123.676 | B44: 46123 | C44: 0.67648148 | D44: Money Movement | E44: Balance Adjustment | I44: Regulatory fee adjustment | J44: 0.11 | K44: 0.11 | L44: 0 | N44: 0 | O44: 0 | W44: USD
A45: 46121.609 | B45: 46121 | C45: 0.60930556 | D45: Trade | E45: Sell to Close | F45: SELL_TO_CLOSE | G45: SPXW 260409P06750000 | H45: Equity Option | I45: Sold 2 SPX 04/09/26 Put 6750.00 @ 0.47 | J45: 92.54 | K45: 94 | L45: 2 | M45: 47 | N45: 0 | O45: -1.46 | P45: 100 | Q45: SPXW | R45: SPX | S45: 46121 | T45: 6750 | U45: PUT | V45: 453144748 | W45: USD
A46: 46121.609 | B46: 46121 | C46: 0.60930556 | D46: Trade | E46: Buy to Close | F46: BUY_TO_CLOSE | G46: SPXW 260409P06790000 | H46: Equity Option | I46: Bought 2 SPX 04/09/26 Put 6790.00 @ 1.07 | J46: -215.45 | K46: -214 | L46: 2 | M46: -107 | N46: 0 | O46: -1.45 | P46: 100 | Q46: SPXW | R46: SPX | S46: 46121 | T46: 6790 | U46: PUT | V46: 453144748 | W46: USD
A47: 46121.554 | B47: 46121 | C47: 0.5541088 | D47: Trade | E47: Sell to Close | F47: SELL_TO_CLOSE | G47: SPXW 260409P06680000 | H47: Equity Option | I47: Sold 1 SPX 04/09/26 Put 6680.00 @ 0.27 | J47: 26.28 | K47: 27 | L47: 1 | M47: 27 | N47: 0 | O47: -0.72 | P47: 100 | Q47: SPXW | R47: SPX | S47: 46121 | T47: 6680 | U47: PUT | V47: 453095985 | W47: USD
A48: 46121.554 | B48: 46121 | C48: 0.5541088 | D48: Trade | E48: Buy to Close | F48: BUY_TO_CLOSE | G48: SPXW 260409P06720000 | H48: Equity Option | I48: Bought 1 SPX 04/09/26 Put 6720.00 @ 0.47 | J48: -47.72 | K48: -47 | L48: 1 | M48: -47 | N48: 0 | O48: -0.72 | P48: 100 | Q48: SPXW | R48: SPX | S48: 46121 | T48: 6720 | U48: PUT | V48: 453095985 | W48: USD
A49: 46121.554 | B49: 46121 | C49: 0.5541088 | D49: Trade | E49: Sell to Close | F49: SELL_TO_CLOSE | G49: SPXW 260409P06680000 | H49: Equity Option | I49: Sold 1 SPX 04/09/26 Put 6680.00 @ 0.27 | J49: 26.28 | K49: 27 | L49: 1 | M49: 27 | N49: 0 | O49: -0.72 | P49: 100 | Q49: SPXW | R49: SPX | S49: 46121 | T49: 6680 | U49: PUT | V49: 453095985 | W49: USD
A50: 46121.554 | B50: 46121 | C50: 0.5541088 | D50: Trade | E50: Buy to Close | F50: BUY_TO_CLOSE | G50: SPXW 260409P06720000 | H50: Equity Option | I50: Bought 1 SPX 04/09/26 Put 6720.00 @ 0.47 | J50: -47.72 | K50: -47 | L50: 1 | M50: -47 | N50: 0 | O50: -0.72 | P50: 100 | Q50: SPXW | R50: SPX | S50: 46121 | T50: 6720 | U50: PUT | V50: 453095985 | W50: USD
A51: 46121.55 | B51: 46121 | C51: 0.54958333 | D51: Trade | E51: Buy to Open | F51: BUY_TO_OPEN | G51: SPXW 260409P06750000 | H51: Equity Option | I51: Bought 2 SPX 04/09/26 Put 6750.00 @ 0.82 | J51: -167.45 | K51: -164 | L51: 2 | M51: -82 | N51: -2 | O51: -1.45 | P51: 100 | Q51: SPXW | R51: SPX | S51: 46121 | T51: 6750 | U51: PUT | V51: 453090692 | W51: USD
...

Sheet PIVOT
B2: Type | C2: Trade
C4: Column Labels
B5: Row Labels | C5: 46106 | D5: 46107 | E5: 46108 | F5: 46119 | G5: 46120 | H5: 46121 | I5: 46126 | J5: 46127 | K5: 46129 | L5: 46136 | M5: Grand Total
B6: TRADE
B7: CALL | C7: 260 | D7: 370 | E7: 278 | F7: 190 | H7: -750 | I7: 85 | J7: 134 | K7: -115 | L7: 620 | M7: 1072
B8: Open | C8: 262 | D8: 370 | E8: 310 | F8: 520 | H8: 880 | I8: 120 | J8: 244 | K8: -635 | L8: -350 | M8: 1721
B9: Close | C9: -2 | E9: -32 | F9: -330 | H9: -1630 | I9: -35 | J9: -110 | K9: 520 | L9: 970 | M9: -649
B10: PUT | C10: 780 | D10: -1880 | E10: -238 | F10: 520 | G10: 0 | H10: 580 | J10: -184 | M10: -422
B11: Open | C11: 888 | D11: 530 | E11: 410 | F11: 540 | G11: 580 | H11: 740 | J11: 306 | M11: 3994
B12: Close | C12: -108 | D12: -2410 | E12: -648 | F12: -20 | G12: -580 | H12: -160 | J12: -490 | M12: -4416
B13: FEES & COMMISSIONS
B14: CALL | C14: -9.82 | D14: -6.88 | E14: -9.82 | F14: -9.82 | G14: 0 | H14: -29.34 | I14: -14.64 | J14: -9.79 | K14: -14.67 | L14: -9.79 | M14: -114.57
B15: Open | C15: -6.91 | D15: -6.88 | E15: -6.91 | F15: -6.91 | G15: 0 | H15: -20.7 | I15: -10.32 | J15: -6.91 | K15: -10.32 | L15: -6.91 | M15: -82.77
B16: Close | C16: -2.91 | D16: 0 | E16: -2.91 | F16: -2.91 | G16: 0 | H16: -8.64 | I16: -4.32 | J16: -2.88 | K16: -4.35 | L16: -2.88 | M16: -31.8
